Workbook

Sheet creatives
A1: =IF(isEmpty, "(empty) You must insert at least one creative", IF(hasBlankLines, "(blank) You have blank lines in the document. Please fill the document without gap", IF(isValid, "(ok) All validation are successful. The sheet is ready to be uploaded", "(invalid) The document contains errors. Please correct the red lines"))) -> (ok) All validation are successful. The sheet is ready to be uploaded
A2: Valid ? | B2: Name* | C2: IAB Category* | D2: Creative Type* | E2: Creative Size* | F2: Creative attribute (optional) | G2: Preview Image URL* | H2: Landing Page* | I2: AdServer* | J2: Script*
A3: =IF(validation!A2,IF(validation!N2,"OK","INVALID"),"") -> OK | B3: Creative name | C3: Automotive | D3: mraid2 | E3: Banner (320x240) | G3: https://publisher.com/ads/preview.png | H3: https://www.tabmo.io | I3: Other | J3: <SCRIPT language='JavaScript1.1' SRC="https://ad.doubleclick.net/ddm/adj/XXXXXX.XXXXXX/XXXXXXX.XXXXXXX;abr=!ie;sz=320x480;ord=[timestamp];dc_lat=;dc_rdid=;tag_for_child_directed_treatment=(https://ad.doubleclick.net/ddm/adi/XXXXXXX.XXXXX/XXXXXXX.XXXXXXX;sz=320x480;ord=[timestamp];dc_lat=;dc_rdid=;tag_for_child_directed_treatment=);click=${HAWK_CLICK_REDIRECT_START}https://events.tabmo.io/track/redirect?url=${HAWK_CLICK_REDIRECT_END}"> //${click_command_redirect}?"> </SCRIPT>
A4: =IF(validation!A3,IF(validation!N3,"OK","INVALID"),"")
A5: =IF(validation!A4,IF(validation!N4,"OK","INVALID"),"")
A6: =IF(validation!A5,IF(validation!N5,"OK","INVALID"),"")
A7: =IF(validation!A6,IF(validation!N6,"OK","INVALID"),"")
A8: =IF(validation!A7,IF(validation!N7,"OK","INVALID"),"")
A9: =IF(validation!A8,IF(validation!N8,"OK","INVALID"),"")
A10: =IF(validation!A9,IF(validation!N9,"OK","INVALID"),"")
A11: =IF(validation!A10,IF(validation!N10,"OK","INVALID"),"")
A12: =IF(validation!A11,IF(validation!N11,"OK","INVALID"),"")
A13: =IF(validation!A12,IF(validation!N12,"OK","INVALID"),"")
A14: =IF(validation!A13,IF(validation!N13,"OK","INVALID"),"")
A15: =IF(validation!A14,IF(validation!N14,"OK","INVALID"),"")
... A201: =IF(validation!A200,IF(validation!N200,"OK","INVALID"),"")
A202: 200 creatives max

Sheet validation
A1: ShoulbBeChecked? | B1: Name | C1: Crea type | D1: Preview | E1: Landing | F1: AdServer | G1: Script | H1: Crea attr | I1: Attribute ID | J1: Size name | K1: Size ID | L1: Cat | M1: Cat ID | N1: Ligne valide ? | O1: Index | P1: All previous are defined | Q1: Last defined
A2: =COUNTIF(creatives!B3:J3, "*")>0 -> TRUE | B2: =IF(OR(NOT(ISTEXT(creatives!B3)), ISBLANK(creatives!B3), LEN(TRIM(creatives!B3))>200), 1, 0) -> 0 | C2: =IF(NOT(ISNUMBER(MATCH(creatives!D3,data!C$2:C$6,0))),1,0) -> 0 | D2: =IF(OR(LEFT(creatives!G3,7)="http://",LEFT(creatives!G3,8)="https://"), 0, 1) -> 0 | E2: =IF(OR(LEFT(creatives!H3,7)="http://",LEFT(creatives!H3,8)="https://"), 0, 1) -> 0 | F2: =IF(NOT(ISNUMBER(MATCH(creatives!I3,data!G$2:G$6,0))),1,0) -> 0 | G2: =IF(ISBLANK(creatives!J3), 1, 0) -> 0 | H2: =IF(NOT(ISBLANK(creatives!F3)),VLOOKUP(creatives!F3,data!I$2:J$29,2,0),"") | I2: =IF(AND(NOT(ISBLANK(creatives!F3)),NOT(ISNUMBER(MATCH(H2,data!J$2:J$29,0)))),1,0) -> 0 | J2: =IF(NOT(ISBLANK(creatives!E3)),VLOOKUP(creatives!E3,data!M$2:N$38,2,0),"") -> 24248c02-b368-4950-9571-058ff4637240 | K2: =IF(NOT(ISNUMBER(MATCH(J2,data!N$2:N$38,0))),1,0) -> 0 | L2: =IF(NOT(ISBLANK(creatives!C3)),VLOOKUP(creatives!C3,data!$A$2:$B$705,2,0),"") -> 1 | M2: =IF(NOT(ISNUMBER(MATCH(L2,data!B$2:B$705,0))),1,0) -> 0 | N2: =IF(NOT(A2),TRUE(),AND(A2,SUM(B2,C2,D2,E2,F2,G2,K2,M2,I2)=0)) -> TRUE | O2: 1 | P2: =IF(A2,COUNTIF(A$2:A2, CONCATENATE("=", TRUE()))=O2, TRUE()) -> TRUE | Q2: =IF(A2,O2,0) -> 1
A3: =COUNTIF(creatives!B4:J4, "*")>0 -> FALSE | B3: =IF(OR(NOT(ISTEXT(creatives!B4)), ISBLANK(creatives!B4), LEN(TRIM(creatives!B4))>200), 1, 0) -> 1 | C3: =IF(NOT(ISNUMBER(MATCH(creatives!D4,data!C$2:C$6,0))),1,0) -> 1 | D3: =IF(OR(LEFT(creatives!G4,7)="http://",LEFT(creatives!G4,8)="https://"), 0, 1) -> 1 | E3: =IF(OR(LEFT(creatives!H4,7)="http://",LEFT(creatives!H4,8)="https://"), 0, 1) -> 1 | F3: =IF(NOT(ISNUMBER(MATCH(creatives!I4,data!G$2:G$6,0))),1,0) -> 1 | G3: =IF(ISBLANK(creatives!J4), 1, 0) -> 1 | H3: =IF(NOT(ISBLANK(creatives!F4)),VLOOKUP(creatives!F4,data!I$2:J$29,2,0),"") | I3: =IF(AND(NOT(ISBLANK(creatives!F4)),NOT(ISNUMBER(MATCH(H3,data!J$2:J$29,0)))),1,0) -> 0 | J3: =IF(NOT(ISBLANK(creatives!E4)),VLOOKUP(creatives!E4,data!M$2:N$38,2,0),"") | K3: =IF(NOT(ISNUMBER(MATCH(J3,data!N$2:N$38,0))),1,0) -> 1 | L3: =IF(NOT(ISBLANK(creatives!C4)),VLOOKUP(creatives!C4,data!$A$2:$B$705,2,0),"") | M3: =IF(NOT(ISNUMBER(MATCH(L3,data!B$2:B$705,0))),1,0) -> 1 | N3: =IF(NOT(A3),TRUE(),AND(A3,SUM(B3,C3,D3,E3,F3,G3,K3,M3,I3)=0)) -> TRUE | O3: 2 | P3: =IF(A3,COUNTIF(A$2:A3, CONCATENATE("=", TRUE()))=O3, TRUE()) -> TRUE | Q3: =IF(A3,O3,0) -> 0
A4: =COUNTIF(creatives!B5:J5, "*")>0 -> FALSE | B4: =IF(OR(NOT(ISTEXT(creatives!B5)), ISBLANK(creatives!B5), LEN(TRIM(creatives!B5))>200), 1, 0) -> 1 | C4: =IF(NOT(ISNUMBER(MATCH(creatives!D5,data!C$2:C$6,0))),1,0) -> 1 | D4: =IF(OR(LEFT(creatives!G5,7)="http://",LEFT(creatives!G5,8)="https://"), 0, 1) -> 1 | E4: =IF(OR(LEFT(creatives!H5,7)="http://",LEFT(creatives!H5,8)="https://"), 0, 1) -> 1 | F4: =IF(NOT(ISNUMBER(MATCH(creatives!I5,data!G$2:G$6,0))),1,0) -> 1 | G4: =IF(ISBLANK(creatives!J5), 1, 0) -> 1 | H4: =IF(NOT(ISBLANK(creatives!F5)),VLOOKUP(creatives!F5,data!I$2:J$29,2,0),"") | I4: =IF(AND(NOT(ISBLANK(creatives!F5)),NOT(ISNUMBER(MATCH(H4,data!J$2:J$29,0)))),1,0) -> 0 | J4: =IF(NOT(ISBLANK(creatives!E5)),VLOOKUP(creatives!E5,data!M$2:N$38,2,0),"") | K4: =IF(NOT(ISNUMBER(MATCH(J4,data!N$2:N$38,0))),1,0) -> 1 | L4: =IF(NOT(ISBLANK(creatives!C5)),VLOOKUP(creatives!C5,data!$A$2:$B$705,2,0),"") | M4: =IF(NOT(ISNUMBER(MATCH(L4,data!B$2:B$705,0))),1,0) -> 1 | N4: =IF(NOT(A4),TRUE(),AND(A4,SUM(B4,C4,D4,E4,F4,G4,K4,M4,I4)=0)) -> TRUE | O4: 3 | P4: =IF(A4,COUNTIF(A$2:A4, CONCATENATE("=", TRUE()))=O4, TRUE()) -> TRUE | Q4: =IF(A4,O4,0) -> 0
A5: =COUNTIF(creatives!B6:J6, "*")>0 -> FALSE | B5: =IF(OR(NOT(ISTEXT(creatives!B6)), ISBLANK(creatives!B6), LEN(TRIM(creatives!B6))>200), 1, 0) -> 1 | C5: =IF(NOT(ISNUMBER(MATCH(creatives!D6,data!C$2:C$6,0))),1,0) -> 1 | D5: =IF(OR(LEFT(creatives!G6,7)="http://",LEFT(creatives!G6,8)="https://"), 0, 1) -> 1 | E5: =IF(OR(LEFT(creatives!H6,7)="http://",LEFT(creatives!H6,8)="https://"), 0, 1) -> 1 | F5: =IF(NOT(ISNUMBER(MATCH(creatives!I6,data!G$2:G$6,0))),1,0) -> 1 | G5: =IF(ISBLANK(creatives!J6), 1, 0) -> 1 | H5: =IF(NOT(ISBLANK(creatives!F6)),VLOOKUP(creatives!F6,data!I$2:J$29,2,0),"") | I5: =IF(AND(NOT(ISBLANK(creatives!F6)),NOT(ISNUMBER(MATCH(H5,data!J$2:J$29,0)))),1,0) -> 0 | J5: =IF(NOT(ISBLANK(creatives!E6)),VLOOKUP(creatives!E6,data!M$2:N$38,2,0),"") | K5: =IF(NOT(ISNUMBER(MATCH(J5,data!N$2:N$38,0))),1,0) -> 1 | L5: =IF(NOT(ISBLANK(creatives!C6)),VLOOKUP(creatives!C6,data!$A$2:$B$705,2,0),"") | M5: =IF(NOT(ISNUMBER(MATCH(L5,data!B$2:B$705,0))),1,0) -> 1 | N5: =IF(NOT(A5),TRUE(),AND(A5,SUM(B5,C5,D5,E5,F5,G5,K5,M5,I5)=0)) -> TRUE | O5: 4 | P5: =IF(A5,COUNTIF(A$2:A5, CONCATENATE("=", TRUE()))=O5, TRUE()) -> TRUE | Q5: =IF(A5,O5,0) -> 0
A6: =COUNTIF(creatives!B7:J7, "*")>0 -> FALSE | B6: =IF(OR(NOT(ISTEXT(creatives!B7)), ISBLANK(creatives!B7), LEN(TRIM(creatives!B7))>200), 1, 0) -> 1 | C6: =IF(NOT(ISNUMBER(MATCH(creatives!D7,data!C$2:C$6,0))),1,0) -> 1 | D6: =IF(OR(LEFT(creatives!G7,7)="http://",LEFT(creatives!G7,8)="https://"), 0, 1) -> 1 | E6: =IF(OR(LEFT(creatives!H7,7)="http://",LEFT(creatives!H7,8)="https://"), 0, 1) -> 1 | F6: =IF(NOT(ISNUMBER(MATCH(creatives!I7,data!G$2:G$6,0))),1,0) -> 1 | G6: =IF(ISBLANK(creatives!J7), 1, 0) -> 1 | H6: =IF(NOT(ISBLANK(creatives!F7)),VLOOKUP(creatives!F7,data!I$2:J$29,2,0),"") | I6: =IF(AND(NOT(ISBLANK(creatives!F7)),NOT(ISNUMBER(MATCH(H6,data!J$2:J$29,0)))),1,0) -> 0 | J6: =IF(NOT(ISBLANK(creatives!E7)),VLOOKUP(creatives!E7,data!M$2:N$38,2,0),"") | K6: =IF(NOT(ISNUMBER(MATCH(J6,data!N$2:N$38,0))),1,0) -> 1 | L6: =IF(NOT(ISBLANK(creatives!C7)),VLOOKUP(creatives!C7,data!$A$2:$B$705,2,0),"") | M6: =IF(NOT(ISNUMBER(MATCH(L6,data!B$2:B$705,0))),1,0) -> 1 | N6: =IF(NOT(A6),TRUE(),AND(A6,SUM(B6,C6,D6,E6,F6,G6,K6,M6,I6)=0)) -> TRUE | O6: 5 | P6: =IF(A6,COUNTIF(A$2:A6, CONCATENATE("=", TRUE()))=O6, TRUE()) -> TRUE | Q6: =IF(A6,O6,0) -> 0
A7: =COUNTIF(creatives!B8:J8, "*")>0 -> FALSE | B7: =IF(OR(NOT(ISTEXT(creatives!B8)), ISBLANK(creatives!B8), LEN(TRIM(creatives!B8))>200), 1, 0) -> 1 | C7: =IF(NOT(ISNUMBER(MATCH(creatives!D8,data!C$2:C$6,0))),1,0) -> 1 | D7: =IF(OR(LEFT(creatives!G8,7)="http://",LEFT(creatives!G8,8)="https://"), 0, 1) -> 1 | E7: =IF(OR(LEFT(creatives!H8,7)="http://",LEFT(creatives!H8,8)="https://"), 0, 1) -> 1 | F7: =IF(NOT(ISNUMBER(MATCH(creatives!I8,data!G$2:G$6,0))),1,0) -> 1 | G7: =IF(ISBLANK(creatives!J8), 1, 0) -> 1 | H7: =IF(NOT(ISBLANK(creatives!F8)),VLOOKUP(creatives!F8,data!I$2:J$29,2,0),"") | I7: =IF(AND(NOT(ISBLANK(creatives!F8)),NOT(ISNUMBER(MATCH(H7,data!J$2:J$29,0)))),1,0) -> 0 | J7: =IF(NOT(ISBLANK(creatives!E8)),VLOOKUP(creatives!E8,data!M$2:N$38,2,0),"") | K7: =IF(NOT(ISNUMBER(MATCH(J7,data!N$2:N$38,0))),1,0) -> 1 | L7: =IF(NOT(ISBLANK(creatives!C8)),VLOOKUP(creatives!C8,data!$A$2:$B$705,2,0),"") | M7: =IF(NOT(ISNUMBER(MATCH(L7,data!B$2:B$705,0))),1,0) -> 1 | N7: =IF(NOT(A7),TRUE(),AND(A7,SUM(B7,C7,D7,E7,F7,G7,K7,M7,I7)=0)) -> TRUE | O7: 6 | P7: =IF(A7,COUNTIF(A$2:A7, CONCATENATE("=", TRUE()))=O7, TRUE()) -> TRUE | Q7: =IF(A7,O7,0) -> 0
A8: =COUNTIF(creatives!B9:J9, "*")>0 -> FALSE | B8: =IF(OR(NOT(ISTEXT(creatives!B9)), ISBLANK(creatives!B9), LEN(TRIM(creatives!B9))>200), 1, 0) -> 1 | C8: =IF(NOT(ISNUMBER(MATCH(creatives!D9,data!C$2:C$6,0))),1,0) -> 1 | D8: =IF(OR(LEFT(creatives!G9,7)="http://",LEFT(creatives!G9,8)="https://"), 0, 1) -> 1 | E8: =IF(OR(LEFT(creatives!H9,7)="http://",LEFT(creatives!H9,8)="https://"), 0, 1) -> 1 | F8: =IF(NOT(ISNUMBER(MATCH(creatives!I9,data!G$2:G$6,0))),1,0) -> 1 | G8: =IF(ISBLANK(creatives!J9), 1, 0) -> 1 | H8: =IF(NOT(ISBLANK(creatives!F9)),VLOOKUP(creatives!F9,data!I$2:J$29,2,0),"") | I8: =IF(AND(NOT(ISBLANK(creatives!F9)),NOT(ISNUMBER(MATCH(H8,data!J$2:J$29,0)))),1,0) -> 0 | J8: =IF(NOT(ISBLANK(creatives!E9)),VLOOKUP(creatives!E9,data!M$2:N$38,2,0),"") | K8: =IF(NOT(ISNUMBER(MATCH(J8,data!N$2:N$38,0))),1,0) -> 1 | L8: =IF(NOT(ISBLANK(creatives!C9)),VLOOKUP(creatives!C9,data!$A$2:$B$705,2,0),"") | M8: =IF(NOT(ISNUMBER(MATCH(L8,data!B$2:B$705,0))),1,0) -> 1 | N8: =IF(NOT(A8),TRUE(),AND(A8,SUM(B8,C8,D8,E8,F8,G8,K8,M8,I8)=0)) -> TRUE | O8: 7 | P8: =IF(A8,COUNTIF(A$2:A8, CONCATENATE("=", TRUE()))=O8, TRUE()) -> TRUE | Q8: =IF(A8,O8,0) -> 0
A9: =COUNTIF(creatives!B10:J10, "*")>0 -> FALSE | B9: =IF(OR(NOT(ISTEXT(creatives!B10)), ISBLANK(creatives!B10), LEN(TRIM(creatives!B10))>200), 1, 0) -> 1 | C9: =IF(NOT(ISNUMBER(MATCH(creatives!D10,data!C$2:C$6,0))),1,0) -> 1 | D9: =IF(OR(LEFT(creatives!G10,7)="http://",LEFT(creatives!G10,8)="https://"), 0, 1) -> 1 | E9: =IF(OR(LEFT(creatives!H10,7)="http://",LEFT(creatives!H10,8)="https://"), 0, 1) -> 1 | F9: =IF(NOT(ISNUMBER(MATCH(creatives!I10,data!G$2:G$6,0))),1,0) -> 1 | G9: =IF(ISBLANK(creatives!J10), 1, 0) -> 1 | H9: =IF(NOT(ISBLANK(creatives!F10)),VLOOKUP(creatives!F10,data!I$2:J$29,2,0),"") | I9: =IF(AND(NOT(ISBLANK(creatives!F10)),NOT(ISNUMBER(MATCH(H9,data!J$2:J$29,0)))),1,0) -> 0 | J9: =IF(NOT(ISBLANK(creatives!E10)),VLOOKUP(creatives!E10,data!M$2:N$38,2,0),"") | K9: =IF(NOT(ISNUMBER(MATCH(J9,data!N$2:N$38,0))),1,0) -> 1 | L9: =IF(NOT(ISBLANK(creatives!C10)),VLOOKUP(creatives!C10,data!$A$2:$B$705,2,0),"") | M9: =IF(NOT(ISNUMBER(MATCH(L9,data!B$2:B$705,0))),1,0) -> 1 | N9: =IF(NOT(A9),TRUE(),AND(A9,SUM(B9,C9,D9,E9,F9,G9,K9,M9,I9)=0)) -> TRUE | O9: 8 | P9: =IF(A9,COUNTIF(A$2:A9, CONCATENATE("=", TRUE()))=O9, TRUE()) -> TRUE | Q9: =IF(A9,O9,0) -> 0
A10: =COUNTIF(creatives!B11:J11, "*")>0 -> FALSE | B10: =IF(OR(NOT(ISTEXT(creatives!B11)), ISBLANK(creatives!B11), LEN(TRIM(creatives!B11))>200), 1, 0) -> 1 | C10: =IF(NOT(ISNUMBER(MATCH(creatives!D11,data!C$2:C$6,0))),1,0) -> 1 | D10: =IF(OR(LEFT(creatives!G11,7)="http://",LEFT(creatives!G11,8)="https://"), 0, 1) -> 1 | E10: =IF(OR(LEFT(creatives!H11,7)="http://",LEFT(creatives!H11,8)="https://"), 0, 1) -> 1 | F10: =IF(NOT(ISNUMBER(MATCH(creatives!I11,data!G$2:G$6,0))),1,0) -> 1 | G10: =IF(ISBLANK(creatives!J11), 1, 0) -> 1 | H10: =IF(NOT(ISBLANK(creatives!F11)),VLOOKUP(creatives!F11,data!I$2:J$29,2,0),"") | I10: =IF(AND(NOT(ISBLANK(creatives!F11)),NOT(ISNUMBER(MATCH(H10,data!J$2:J$29,0)))),1,0) -> 0 | J10: =IF(NOT(ISBLANK(creatives!E11)),VLOOKUP(creatives!E11,data!M$2:N$38,2,0),"") | K10: =IF(NOT(ISNUMBER(MATCH(J10,data!N$2:N$38,0))),1,0) -> 1 | L10: =IF(NOT(ISBLANK(creatives!C11)),VLOOKUP(creatives!C11,data!$A$2:$B$705,2,0),"") | M10: =IF(NOT(ISNUMBER(MATCH(L10,data!B$2:B$705,0))),1,0) -> 1 | N10: =IF(NOT(A10),TRUE(),AND(A10,SUM(B10,C10,D10,E10,F10,G10,K10,M10,I10)=0)) -> TRUE | O10: 9 | P10: =IF(A10,COUNTIF(A$2:A10, CONCATENATE("=", TRUE()))=O10, TRUE()) -> TRUE | Q10: =IF(A10,O10,0) -> 0
A11: =COUNTIF(creatives!B12:J12, "*")>0 -> FALSE | B11: =IF(OR(NOT(ISTEXT(creatives!B12)), ISBLANK(creatives!B12), LEN(TRIM(creatives!B12))>200), 1, 0) -> 1 | C11: =IF(NOT(ISNUMBER(MATCH(creatives!D12,data!C$2:C$6,0))),1,0) -> 1 | D11: =IF(OR(LEFT(creatives!G12,7)="http://",LEFT(creatives!G12,8)="https://"), 0, 1) -> 1 | E11: =IF(OR(LEFT(creatives!H12,7)="http://",LEFT(creatives!H12,8)="https://"), 0, 1) -> 1 | F11: =IF(NOT(ISNUMBER(MATCH(creatives!I12,data!G$2:G$6,0))),1,0) -> 1 | G11: =IF(ISBLANK(creatives!J12), 1, 0) -> 1 | H11: =IF(NOT(ISBLANK(creatives!F12)),VLOOKUP(creatives!F12,data!I$2:J$29,2,0),"") | I11: =IF(AND(NOT(ISBLANK(creatives!F12)),NOT(ISNUMBER(MATCH(H11,data!J$2:J$29,0)))),1,0) -> 0 | J11: =IF(NOT(ISBLANK(creatives!E12)),VLOOKUP(creatives!E12,data!M$2:N$38,2,0),"") | K11: =IF(NOT(ISNUMBER(MATCH(J11,data!N$2:N$38,0))),1,0) -> 1 | L11: =IF(NOT(ISBLANK(creatives!C12)),VLOOKUP(creatives!C12,data!$A$2:$B$705,2,0),"") | M11: =IF(NOT(ISNUMBER(MATCH(L11,data!B$2:B$705,0))),1,0) -> 1 | N11: =IF(NOT(A11),TRUE(),AND(A11,SUM(B11,C11,D11,E11,F11,G11,K11,M11,I11)=0)) -> TRUE | O11: 10 | P11: =IF(A11,COUNTIF(A$2:A11, CONCATENATE("=", TRUE()))=O11, TRUE()) -> TRUE | Q11: =IF(A11,O11,0) -> 0
A12: =COUNTIF(creatives!B13:J13, "*")>0 -> FALSE | B12: =IF(OR(NOT(ISTEXT(creatives!B13)), ISBLANK(creatives!B13), LEN(TRIM(creatives!B13))>200), 1, 0) -> 1 | C12: =IF(NOT(ISNUMBER(MATCH(creatives!D13,data!C$2:C$6,0))),1,0) -> 1 | D12: =IF(OR(LEFT(creatives!G13,7)="http://",LEFT(creatives!G13,8)="https://"), 0, 1) -> 1 | E12: =IF(OR(LEFT(creatives!H13,7)="http://",LEFT(creatives!H13,8)="https://"), 0, 1) -> 1 | F12: =IF(NOT(ISNUMBER(MATCH(creatives!I13,data!G$2:G$6,0))),1,0) -> 1 | G12: =IF(ISBLANK(creatives!J13), 1, 0) -> 1 | H12: =IF(NOT(ISBLANK(creatives!F13)),VLOOKUP(creatives!F13,data!I$2:J$29,2,0),"") | I12: =IF(AND(NOT(ISBLANK(creatives!F13)),NOT(ISNUMBER(MATCH(H12,data!J$2:J$29,0)))),1,0) -> 0 | J12: =IF(NOT(ISBLANK(creatives!E13)),VLOOKUP(creatives!E13,data!M$2:N$38,2,0),"") | K12: =IF(NOT(ISNUMBER(MATCH(J12,data!N$2:N$38,0))),1,0) -> 1 | L12: =IF(NOT(ISBLANK(creatives!C13)),VLOOKUP(creatives!C13,data!$A$2:$B$705,2,0),"") | M12: =IF(NOT(ISNUMBER(MATCH(L12,data!B$2:B$705,0))),1,0) -> 1 | N12: =IF(NOT(A12),TRUE(),AND(A12,SUM(B12,C12,D12,E12,F12,G12,K12,M12,I12)=0)) -> TRUE | O12: 11 | P12: =IF(A12,COUNTIF(A$2:A12, CONCATENATE("=", TRUE()))=O12, TRUE()) -> TRUE | Q12: =IF(A12,O12,0) -> 0
A13: =COUNTIF(creatives!B14:J14, "*")>0 -> FALSE | B13: =IF(OR(NOT(ISTEXT(creatives!B14)), ISBLANK(creatives!B14), LEN(TRIM(creatives!B14))>200), 1, 0) -> 1 | C13: =IF(NOT(ISNUMBER(MATCH(creatives!D14,data!C$2:C$6,0))),1,0) -> 1 | D13: =IF(OR(LEFT(creatives!G14,7)="http://",LEFT(creatives!G14,8)="https://"), 0, 1) -> 1 | E13: =IF(OR(LEFT(creatives!H14,7)="http://",LEFT(creatives!H14,8)="https://"), 0, 1) -> 1 | F13: =IF(NOT(ISNUMBER(MATCH(creatives!I14,data!G$2:G$6,0))),1,0) -> 1 | G13: =IF(ISBLANK(creatives!J14), 1, 0) -> 1 | H13: =IF(NOT(ISBLANK(creatives!F14)),VLOOKUP(creatives!F14,data!I$2:J$29,2,0),"") | I13: =IF(AND(NOT(ISBLANK(creatives!F14)),NOT(ISNUMBER(MATCH(H13,data!J$2:J$29,0)))),1,0) -> 0 | J13: =IF(NOT(ISBLANK(creatives!E14)),VLOOKUP(creatives!E14,data!M$2:N$38,2,0),"") | K13: =IF(NOT(ISNUMBER(MATCH(J13,data!N$2:N$38,0))),1,0) -> 1 | L13: =IF(NOT(ISBLANK(creatives!C14)),VLOOKUP(creatives!C14,data!$A$2:$B$705,2,0),"") | M13: =IF(NOT(ISNUMBER(MATCH(L13,data!B$2:B$705,0))),1,0) -> 1 | N13: =IF(NOT(A13),TRUE(),AND(A13,SUM(B13,C13,D13,E13,F13,G13,K13,M13,I13)=0)) -> TRUE | O13: 12 | P13: =IF(A13,COUNTIF(A$2:A13, CONCATENATE("=", TRUE()))=O13, TRUE()) -> TRUE | Q13: =IF(A13,O13,0) -> 0
... A201: =COUNTIF(creatives!B202:J202, "*")>0 -> FALSE | B201: =IF(OR(NOT(ISTEXT(creatives!B202)), ISBLANK(creatives!B202), LEN(TRIM(creatives!B202))>200), 1, 0) -> 1 | C201: =IF(NOT(ISNUMBER(MATCH(creatives!D202,data!C$2:C$6,0))),1,0) -> 1 | D201: =IF(OR(LEFT(creatives!G202,7)="http://",LEFT(creatives!G202,8)="https://"), 0, 1) -> 1 | E201: =IF(OR(LEFT(creatives!H202,7)="http://",LEFT(creatives!H202,8)="https://"), 0, 1) -> 1 | F201: =IF(NOT(ISNUMBER(MATCH(creatives!I202,data!G$2:G$6,0))),1,0) -> 1 | G201: =IF(ISBLANK(creatives!J202), 1, 0) -> 1 | H201: =IF(NOT(ISBLANK(creatives!F202)),VLOOKUP(creatives!F202,data!I$2:J$29,2,0),"") | I201: =IF(AND(NOT(ISBLANK(creatives!F202)),NOT(ISNUMBER(MATCH(H201,data!J$2:J$29,0)))),1,0) -> 0 | J201: =IF(NOT(ISBLANK(creatives!E202)),VLOOKUP(creatives!E202,data!M$2:N$38,2,0),"") | K201: =IF(NOT(ISNUMBER(MATCH(J201,data!N$2:N$38,0))),1,0) -> 1 | L201: =IF(NOT(ISBLANK(creatives!C202)),VLOOKUP(creatives!C202,data!$A$2:$B$705,2,0),"") | M201: =IF(NOT(ISNUMBER(MATCH(L201,data!B$2:B$705,0))),1,0) -> 1 | N201: =IF(NOT(A201),TRUE(),AND(A201,SUM(B201,C201,D201,E201,F201,G201,K201,M201,I201)=0)) -> TRUE | O201: 200 | P201: =IF(A201,COUNTIF(A$2:A201, CONCATENATE("=", TRUE()))=O201, TRUE()) -> TRUE | Q201: =IF(A201,O201,0) -> 0

Sheet data
A1: IAB Cat name | B1: IAB Cat id | C1: Creative Type | G1: Adservers | I1: Creatives attributes | M1: Creative Size Name | N1: Creative Size ID
A2: Automotive | B2: 1 | C2: mraid2 | G2: Other | I2: Audio Ad (Auto Play) | J2: 1 | M2: Rectangle banner (300x100) | N2: c817eaf7-6ff5-48c3-8b0f-dbef410b19a1
A3: Auto Body Styles | B3: 2 | C3: mraid1 | G3: Sizmek | I3: Audio Ad (User Initiated) | J3: 2 | M3: Standard banner (300x50) | N3: 0e38eab8-55fc-41ee-b17a-4d76d4ed1e17
A4: Commercial Trucks | B4: 3 | C4: javascript | G4: DCM | I4: Expandable (Automatic) | J4: 3 | M4: Rectangle banner (300x600) | N4: d9ce91ef-e732-4980-9a62-4a8b6430f3b1
A5: Sedan | B5: 4 | C5: html | G5: Adform | I5: Expandable (User Initiated - Click) | J5: 4 | M5: Square banner(300x250) | N5: b3bb2b24-5884-11e5-8334-3379b6ba6612
A6: Station Wagon | B6: 5 | C6: ormma | G6: Sting | I6: Expandable (User Initiated - Rollover) | J6: 5 | M6: Banner (320x50) | N6: b3bb270a-5884-11e5-8333-4f7d54f179bb
A7: SUV | B7: 6 | I7: In-Banner Video Ad (Auto Play) | J7: 6 | M7: Banner (320x240) | N7: 24248c02-b368-4950-9571-058ff4637240
A8: Van | B8: 7 | I8: In-Banner Video Ad (User Initiated) | J8: 7 | M8: Full screen portrait (320x480) | N8: b3bb2c14-5884-11e5-8336-f7a99d935cae
A9: Convertible | B9: 8 | I9: Pop (e.g., Over, Under, or upon Exit) | J9: 8 | M9: Rectangle banner (320x100) | N9: 17aba06c-f2fd-44b1-b629-78955cd6cc50
A10: Coupe | B10: 9 | I10: Provocative or Suggestive Imagery | J10: 9 | M10: Full screen landscape (480x320) | N10: b3bb2bc4-5884-11e5-8335-57e65f6c74e4
A11: Crossover | B11: 10 | I11: Shaky, Flashing, Flickering, Extreme Animation, Smileys | J11: 10 | M11: Skyscraper (120x600) | N11: b3bb2d0e-5884-11e5-8339-5706740d0ad8
A12: Hatchback | B12: 11 | I12: Surveys | J12: 11 | M12: Small landscape banner (468x60) | N12: b3bb2c64-5884-11e5-8337-3732e3294a07
A13: Microcar | B13: 12 | I13: Text Only | J13: 12 | M13: Banner (728x90) | N13: b3bb2cb4-5884-11e5-8338-0f49c2f0ae2c
A14: Minivan | B14: 13 | I14: User Interactive (e.g., Embedded Games) | J14: 13 | M14: Full screen portrait (768x1024) | N14: b3bb2e30-5884-11e5-833b-23fc3a8ffec3
A15: Off-Road Vehicles | B15: 14 | I15: Windows Dialog or Alert Style | J15: 14 | M15: Full screen landscape (1024x768) | N15: b3bb2de0-5884-11e5-833a-df6a96602270
A16: Pickup Trucks | B16: 15 | I16: Has audio on/off button | J16: 15 | M16: 980x600 | N16: 62951b21-50d0-4ff9-be12-a5a74ffae1d4
A17: Auto Type | B17: 16 | I17: Ad can be skipped (e.g., skip button on preroll video) | J17: 16 | M17: 980x300 | N17: 68dd42b7-7d71-4686-89a4-3c354a75191b
A18: Budget Cars | B18: 17 | I18: Belly Fat | J18: 14018 | M18: 580x400 | N18: ce44aac1-7c85-4919-ab4f-9df37113a005
... A29: Road-Side Assistance | B29: 28 | I29: Teeth Whitening | J29: 14019 | M29: 180x500 | N29: 271d65c0-8bbd-40f6-b7db-5cc0c6fac3da
A30: Scooters | B30: 29 | M30: 930x180 | N30: 96430848-20a3-4389-90a0-90430b69ad2d
A31: Auto Buying and Selling | B31: 30 | M31: 980x400 | N31: 567cea9c-84ca-49fc-9da6-79a95651f8e2
A32: Auto Insurance | B32: 31 | M32: 600x600 | N32: ef9ab7c4-aacf-400b-9c88-178bc5956b4b
A33: Auto Parts | B33: 32 | M33: 580x500 | N33: a3c819e8-6b38-43a6-acd1-af740c041ffb
A34: Auto Recalls | B34: 33 | M34: 1920x1080 (desktop) | N34: cfa24164-8339-463d-9571-e7512457b75a
A35: Auto Repair | B35: 34 | M35: 980x552 | N35: 42a111ba-d387-4986-9a07-260a606d7168
A36: Auto Safety | B36: 35 | M36: 620x891 | N36: 270f9fc7-124b-4ed5-bb1b-d1367575e9f4
A37: Auto Shows | B37: 36 | M37: 300x500 | N37: 04d6bc92-36df-4aed-a041-d90b21af39c4
A38: Auto Technology | B38: 37 | M38: 970x250 | N38: 5e73da9a-b467-41b1-8165-32fda8879903
A39: Auto Infotainment Technologies | B39: 38
A40: Auto Navigation Systems | B40: 39
A41: Auto Safety Technologies | B41: 40
A42: Auto Rentals | B42: 41
A43: Books and Literature | B43: 42
A44: Art and Photography | B44: 43
A45: Biographies | B45: 44
A46: Comics and Graphic Novels | B46: 46
A47: Fiction | B47: 48
A48: Poetry | B48: 49
A49: Young Adult | B49: 51
A50: Business and Finance | B50: 52
...

Sheet metadata
A1: version | B1: 1.0.0
A2: Lines defined | B2: =MAX(validation!Q2:Q201) -> 1
A3: Fully compliant? | B3: =AND(hasntErrors,NOT(isEmpty),NOT(hasBlankLines)) -> TRUE
A4: without errors | B4: =COUNTIF(validation!N2:N201, CONCATENATE("=", FALSE()))=0 -> TRUE
A5: is Empty | B5: =COUNTIF(validation!A2:A201, CONCATENATE("=", TRUE()) )=0 -> FALSE
A6: has Blank Lines? | B6: =COUNTIF(validation!P2:P201, CONCATENATE("=", FALSE()))<>0 -> FALSE
